Workbook
Name Slicer_Category: #N/A
Name Slicer_Payment_Mode: #N/A
Name Slicer_Status: #N/A
Name Slicer_Transaction_Type: #N/A
Name Slicer_Warehouse_ID: #N/A

Sheet Products_Master
A1: Product_ID | B1: Product_Name | C1: Category | D1: Sub_Category | E1: Brand | F1: Unit_of_Measure | G1: Standard_Cost | H1: Standard_Selling_Price | I1: Reorder_Level
A2: P1001 | B2: Dell Business Laptop 1 | C2: Laptops | D2: Business Laptop | E2: Dell | F2: PCS | G2: 45000 | H2: 54900 | I2: 10
A3: P1002 | B3: HP Business Laptop 2 | C3: Laptops | D3: Business Laptop | E3: HP | F3: PCS | G3: 45500 | H3: 55510 | I3: 10
A4: P1003 | B4: Lenovo Business Laptop 3 | C4: Laptops | D4: Business Laptop | E4: Lenovo | F4: PCS | G4: 46000 | H4: 56120 | I4: 10
A5: P1004 | B5: ASUS Business Laptop 4 | C5: Laptops | D5: Business Laptop | E5: ASUS | F5: PCS | G5: 46500 | H5: 56730 | I5: 10
A6: P1005 | B6: Acer Business Laptop 5 | C6: Laptops | D6: Business Laptop | E6: Acer | F6: PCS | G6: 47000 | H6: 57340 | I6: 10
A7: P1006 | B7: Dell Business Laptop 6 | C7: Laptops | D7: Business Laptop | E7: Dell | F7: PCS | G7: 46200 | H7: 56364 | I7: 10
A8: P1007 | B8: HP Business Laptop 7 | C8: Laptops | D8: Business Laptop | E8: HP | F8: PCS | G8: 46700 | H8: 56974 | I8: 10
A9: P1008 | B9: Lenovo Business Laptop 8 | C9: Laptops | D9: Business Laptop | E9: Lenovo | F9: PCS | G9: 47200 | H9: 57584 | I9: 10
A10: P1009 | B10: ASUS Business Laptop 9 | C10: Laptops | D10: Business Laptop | E10: ASUS | F10: PCS | G10: 47700 | H10: 58194 | I10: 10
A11: P1010 | B11: Acer Business Laptop 10 | C11: Laptops | D11: Business Laptop | E11: Acer | F11: PCS | G11: 48200 | H11: 58804 | I11: 10
A12: P1011 | B12: Dell Business Laptop 11 | C12: Laptops | D12: Business Laptop | E12: Dell | F12: PCS | G12: 47400 | H12: 57828 | I12: 10
A13: P1012 | B13: HP Business Laptop 12 | C13: Laptops | D13: Business Laptop | E13: HP | F13: PCS | G13: 47900 | H13: 58438 | I13: 10
... A101: P1100 | B101: Logitech Headset 6 | C101: Audio Devices | D101: Headset | E101: Logitech | F101: PCS | G101: 2000 | H101: 2440 | I101: 25

Sheet Suppliers_Masters
A1: Supplier_ID | B1: Supplier_Name | C1: City | D1: State | E1: Supplier_Rating | F1: Lead_Time_Days | G1: Contact_Person
A2: SUP001 | B2: Dell Technologies India | C2: Bengaluru | D2: Karnataka | E2: 4.8 | F2: 5 | G2: Rahul Sharma
A3: SUP002 | B3: HP India Pvt. Ltd. | C3: Mumbai | D3: Maharashtra | E3: 4.7 | F3: 6 | G3: Amit Verma
A4: SUP003 | B4: Lenovo India Pvt. Ltd. | C4: Bengaluru | D4: Karnataka | E4: 4.6 | F4: 7 | G4: Neha Singh
A5: SUP004 | B5: ASUS India | C5: Mumbai | D5: Maharashtra | E5: 4.5 | F5: 6 | G5: Rohan Patil
A6: SUP005 | B6: Acer India | C6: Chennai | D6: Tamil Nadu | E6: 4.4 | F6: 7 | G6: Priya Nair
A7: SUP006 | B7: Samsung India Electronics | C7: Noida | D7: Uttar Pradesh | E7: 4.8 | F7: 5 | G7: Ankit Gupta
A8: SUP007 | B8: Logitech India | C8: Pune | D8: Maharashtra | E8: 4.7 | F8: 4 | G8: Sneha Joshi
A9: SUP008 | B9: TP-Link India | C9: New Delhi | D9: Delhi | E9: 4.5 | F9: 5 | G9: Vikas Mehta
A10: SUP009 | B10: Cisco India | C10: Bengaluru | D10: Karnataka | E10: 4.9 | F10: 8 | G10: Karan Rao
A11: SUP010 | B11: Seagate India | C11: Pune | D11: Maharashtra | E11: 4.6 | F11: 6 | G11: Pooja Kulkarni
A12: SUP011 | B12: Western Digital India | C12: Mumbai | D12: Maharashtra | E12: 4.7 | F12: 5 | G12: Saurabh Jain
A13: SUP012 | B13: Canon India | C13: Gurugram | D13: Haryana | E13: 4.5 | F13: 6 | G13: Manish Yadav
... A21: SUP020 | B21: Zebronics India | C21: Chennai | D21: Tamil Nadu | E21: 4.3 | F21: 5 | G21: Kavya Reddy

Sheet Warehouses_Master
A1: Warehouse_ID | B1: Warehouse_Name | C1: City | D1: State | E1: Capacity_Units | F1: Warehouse_Type
A2: WH001 | B2: Pune Central Warehouse | C2: Pune | D2: Maharashtra | E2: 25000 | F2: Central
A3: WH002 | B3: Mumbai Distribution Center | C3: Mumbai | D3: Maharashtra | E3: 20000 | F3: Regional
A4: WH003 | B4: Nagpur Logistics Hub | C4: Nagpur | D4: Maharashtra | E4: 18000 | F4: Regional
A5: WH004 | B5: Hyderabad Fulfillment Center | C5: Hyderabad | D5: Telangana | E5: 22000 | F5: Regional
A6: WH005 | B6: Bengaluru South Warehouse | C6: Bengaluru | D6: Karnataka | E6: 30000 | F6: Central

Sheet Employees_Master
A1: Employee_ID | B1: Employee_Name | C1: Department | D1: Designation | E1: Location
A2: EMP001 | B2: Aarav Sharma | C2: Inventory | D2: Inventory Executive | E2: Pune
A3: EMP002 | B3: Neha Patil | C3: Inventory | D3: Inventory Executive | E3: Mumbai
A4: EMP003 | B4: Rahul Verma | C4: Inventory | D4: Warehouse Executive | E4: Nagpur
A5: EMP004 | B5: Priya Kulkarni | C5: Inventory | D5: Warehouse Executive | E5: Hyderabad
A6: EMP005 | B6: Rohan Deshmukh | C6: Procurement | D6: Procurement Executive | E6: Pune
A7: EMP006 | B7: Sneha Joshi | C7: Procurement | D7: Procurement Executive | E7: Mumbai
A8: EMP007 | B8: Karan Mehta | C8: Procurement | D8: Senior Procurement Executive | E8: Bengaluru
A9: EMP008 | B9: Anjali Singh | C9: Procurement | D9: Procurement Analyst | E9: Chennai
A10: EMP009 | B10: Vikram Rao | C10: Operations | D10: Operations Executive | E10: Pune
A11: EMP010 | B11: Pooja Nair | C11: Operations | D11: Operations Executive | E11: Nagpur
A12: EMP011 | B12: Aditya Jain | C12: Operations | D12: Operations Analyst | E12: Hyderabad
... A26: EMP025 | B26: Ishita Kapoor | C26: Logistics | D26: Logistics Manager | E26: Hyderabad

Sheet Calendar
A1: Date | B1: Day | C1: Day_Name | D1: Week_No | E1: Month_No | F1: Month_Name | G1: Quarter | H1: Year | I1: Is_Weekend | J1: Financial_Year | K1: Financial_Quarter
A2: 01-01-2025 | B2: 1 | C2: Wednesday | D2: 1 | E2: 1 | F2: January | G2: Q1 | H2: 2025 | I2: No | J2: FY 2024-25 | K2: FQ4
A3: 02-01-2025 | B3: 2 | C3: Thursday | D3: 1 | E3: 1 | F3: January | G3: Q1 | H3: 2025 | I3: No | J3: FY 2024-25 | K3: FQ4
A4: 03-01-2025 | B4: 3 | C4: Friday | D4: 1 | E4: 1 | F4: January | G4: Q1 | H4: 2025 | I4: No | J4: FY 2024-25 | K4: FQ4
A5: 04-01-2025 | B5: 4 | C5: Saturday | D5: 1 | E5: 1 | F5: January | G5: Q1 | H5: 2025 | I5: Yes | J5: FY 2024-25 | K5: FQ4
A6: 05-01-2025 | B6: 5 | C6: Sunday | D6: 1 | E6: 1 | F6: January | G6: Q1 | H6: 2025 | I6: Yes | J6: FY 2024-25 | K6: FQ4
A7: 06-01-2025 | B7: 6 | C7: Monday | D7: 2 | E7: 1 | F7: January | G7: Q1 | H7: 2025 | I7: No | J7: FY 2024-25 | K7: FQ4
A8: 07-01-2025 | B8: 7 | C8: Tuesday | D8: 2 | E8: 1 | F8: January | G8: Q1 | H8: 2025 | I8: No | J8: FY 2024-25 | K8: FQ4
A9: 08-01-2025 | B9: 8 | C9: Wednesday | D9: 2 | E9: 1 | F9: January | G9: Q1 | H9: 2025 | I9: No | J9: FY 2024-25 | K9: FQ4
A10: 09-01-2025 | B10: 9 | C10: Thursday | D10: 2 | E10: 1 | F10: January | G10: Q1 | H10: 2025 | I10: No | J10: FY 2024-25 | K10: FQ4
A11: 10-01-2025 | B11: 10 | C11: Friday | D11: 2 | E11: 1 | F11: January | G11: Q1 | H11: 2025 | I11: No | J11: FY 2024-25 | K11: FQ4
A12: 11-01-2025 | B12: 11 | C12: Saturday | D12: 2 | E12: 1 | F12: January | G12: Q1 | H12: 2025 | I12: Yes | J12: FY 2024-25 | K12: FQ4
A13: 12-01-2025 | B13: 12 | C13: Sunday | D13: 2 | E13: 1 | F13: January | G13: Q1 | H13: 2025 | I13: Yes | J13: FY 2024-25 | K13: FQ4
... A731: 31-12-2026 | B731: 31 | C731: Thursday | D731: 53 | E731: 12 | F731: December | G731: Q4 | H731: 2026 | I731: No | J731: FY 2026-27 | K731: FQ3

Sheet Sales_Trend
A1: Transaction_Type | B1: (All)
A3: Row Labels | B3: Sum of Total_Value
A4: 2025 | B4: 1889750745
A5: Jan | B5: 154422626
A6: Feb | B6: 163187939
A7: Mar | B7: 177401501
A8: Apr | B8: 150856288
A9: May | B9: 163442278
A10: Jun | B10: 162467525
A11: Jul | B11: 159248916
A12: Aug | B12: 146717528
A13: Sep | B13: 169887116
A14: Oct | B14: 156348491
A15: Nov | B15: 141817415
... A30: Grand Total | B30: 3815308401

Sheet Category Wise Sales 
A1: Transaction_Type | B1: (All)
A3: Row Labels | B3: Sum of Total_Value
A4: Electronics | B4: 1967152262
A5: Furniture | B5: 757068446
A6: Stationery | B6: 1091087693
A7: Grand Total | B7: 3815308401

Sheet Sales by Warehouse
A1: Transaction_Type | B1: (All)
A3: Row Labels | B3: Sum of Total_Value
B4: 407530
A5: W01 | B5: 803827680
A6: W02 | B6: 749372598
A7: W03 | B7: 831714835
A8: W04 | B8: 691056091
A9: W05 | B9: 738929667
A10: Grand Total | B10: 3815308401

Sheet Transaction Analysis
A3: Row Labels | B3: Sum of Total_Value
A4: Adjustment | B4: 891142236
A5: Purchase | B5: 900263468
A6: Return | B6: 1005857263
A7: Sale | B7: 1018045434
A8: Grand Total | B8: 3815308401

Sheet Top 10 sales Product
A1: Transaction_Type | B1: (All)
A3: Row Labels | B3: Sum of Total_Value
A4: Office Chair | B4: 436176948
A5: Monitor | B5: 429459556
A6: Mouse | B6: 422105054
A7: Keyboard | B7: 402900066
A8: File Folder | B8: 368003447
A9: Notebook | B9: 367594825
A10: Laptop | B10: 362486633
A11: Pen | B11: 355489421
A12: Printer | B12: 350200953
A13: Office Desk | B13: 320891498
A14: Grand Total | B14: 3815308401

Sheet Stocks Analysis
A3: Row Labels | B3: Sum of Stock_Before | C3: Sum of Stock_After
B4: 280 | C4: 363
A5: W01 | B5: 164331 | C5: 170261
A6: W02 | B6: 157559 | C6: 166060
A7: W03 | B7: 177201 | C7: 185014
A8: W04 | B8: 149041 | C8: 155566
A9: W05 | B9: 163441 | C9: 171581
A10: Grand Total | B10: 811853 | C10: 848845

Sheet Payment Mode Analysis 
A1: Transaction_Type | B1: (All)
A3: Row Labels | B3: Sum of Total_Value
A4: Card | B4: 930970668
A5: Cash | B5: 946545687
A6: Credit | B6: 981068753
A7: UPI | B7: 956723293
A8: Grand Total | B8: 3815308401

Sheet Inventory_Transaction
A1: Transaction_ID | B1: Transaction_Date | C1: Product_ID | D1: Product_Name | E1: Category | F1: Sub_Category | G1: Supplier_ID | H1: Warehouse_ID | I1: Transaction_Type | J1: Quantity | K1: Unit_Price | L1: Total_Value | M1: Stock_Before | N1: Stock_After | O1: Employee_ID | P1: Customer_ID | Q1: Payment_Mode | R1: Status | S1: Remarks | T1: Duplicates | U1: Miossing Transaction | V1: Invalid Product | W1: Invalid Supplier | X1: Invalid Warehouse | Y1: Invalid Employee | Z1: Stocks check | AA1: Total value check | AB1: Stock_After Check | AC1: Quantity_Check | AD1: Stock_Status
A2: T00001 | B2: 45800 | C2: P002 | D2: Keyboard | E2: Electronics | F2: Accessories | G2: S004 | H2: W05 | I2: Purchase | J2: 95 | K2: 18074 | L2: 1717030 | M2: 175 | N2: 270 | O2: E003 | Q2: Credit | R2: Completed | S2: Regular Transaction | T2: =IF(COUNTIF(T4,Q14)>1,"Duplicate","OK") -> OK | U2: =IF(Table2[[#This Row],[Transaction_ID]]="","Missing","OK") -> OK | V2: =IF(COUNTIF(Table2[[#This Row],[Product_ID]],Table2[[#This Row],[Product_ID]])=0,"Invalid Product","OK") -> OK | W2: =IF(COUNTIF(Table2[[#This Row],[Supplier_ID]],Table2[[#This Row],[Supplier_ID]])=0,"Invalid Supplier","OK") -> OK | X2: =IF(COUNTIF(Table2[[#This Row],[Warehouse_ID]],Table2[[#This Row],[Warehouse_ID]])=0,"Invalid Warehouse","OK") -> OK | Y2: =IF(COUNTIF(Table2[[#This Row],[Employee_ID]],Table2[[#This Row],[Employee_ID]])=0,"Invalid Employee","OK") -> OK | Z2: =IF(Table2[[#This Row],[Stock_After]]=Table2[[#This Row],[Stock_After]]+Table2[[#This Row],[Stock_After]]-Table2[[#This Row],[Stock_After]]-Table2[[#This Row],[Stock_After]]+Table2[[#This Row],[Stock_After]],"OK","Error") -> OK | AA2: =IF(ROUND(Table2[[#This Row],[Total_Value]],2)=ROUND(Table2[[#This Row],[Quantity]]*Table2[[#This Row],[Unit_Price]],2),"OK","Error") -> OK | AB2: =IF(Table2[[#This Row],[Transaction_Type]]="Purchase", IF(Table2[[#This Row],[Stock_After]]=Table2[[#This Row],[Stock_Before]]+Table2[[#This Row],[Quantity]], "OK", "Error"), IF(Table2[[#This Row],[Transaction_Type]]="Return", IF(Table2[[#This Row],[Stock_After]]=Table2[[#This Row],[Stock_Before]]+Table2[[#This Row],[Quantity]], "OK", "Error"), IF(Table2[[#This Row],[Transaction_Type]]="Sale", IF(Table2[[#This Row],[Stock_After]]=MAX(0, Table2[[#This Row],[Stock_Before]]-Table2[[#This Row],[Quantity]]), "OK", "Error"), IF(Table2[[#This Row],[Transaction_Type]]="Adjustment", IF(Table2[[#This Row],[Stock_After]]>=0, "OK", "Error"), "Check")))) -> OK | AC2: =IF(AND(Table2[[#This Row],[Quantity]]>=0,Table2[[#This Row],[Unit_Price]]>=0),"OK","Error") -> OK | AD2: =IF(Table2[[#This Row],[Stock_After]]=0,"Stock-Out",IF(Table2[[#This Row],[Stock_After]]<=10,"Low Stock","Healthy")) -> Healthy
A3: T00002 | B3: 46274 | C3: P001 | D3: Laptop | E3: Electronics | F3: Computers | G3: S001 | H3: W05 | I3: Purchase | J3: 12 | K3: 14378 | L3: 172536 | M3: 169 | N3: 181 | O3: E007 | Q3: Credit | R3: Pending | S3: Regular Transaction | T3: =IF(COUNTIF(T5,Q15)>1,"Duplicate","OK") -> OK | U3: =IF(Table2[[#This Row],[Transaction_ID]]="","Missing","OK") -> OK | V3: =IF(COUNTIF(Table2[[#This Row],[Product_ID]],Table2[[#This Row],[Product_ID]])=0,"Invalid Product","OK") -> OK | W3: =IF(COUNTIF(Table2[[#This Row],[Supplier_ID]],Table2[[#This Row],[Supplier_ID]])=0,"Invalid Supplier","OK") -> OK | X3: =IF(COUNTIF(Table2[[#This Row],[Warehouse_ID]],Table2[[#This Row],[Warehouse_ID]])=0,"Invalid Warehouse","OK") -> OK | Y3: =IF(COUNTIF(Table2[[#This Row],[Employee_ID]],Table2[[#This Row],[Employee_ID]])=0,"Invalid Employee","OK") -> OK | Z3: =IF(Table2[[#This Row],[Stock_After]]=Table2[[#This Row],[Stock_After]]+Table2[[#This Row],[Stock_After]]-Table2[[#This Row],[Stock_After]]-Table2[[#This Row],[Stock_After]]+Table2[[#This Row],[Stock_After]],"OK","Error") -> OK | AA3: =IF(ROUND(Table2[[#This Row],[Total_Value]],2)=ROUND(Table2[[#This Row],[Quantity]]*Table2[[#This Row],[Unit_Price]],2),"OK","Error") -> OK | AB3: =IF(Table2[[#This Row],[Transaction_Type]]="Purchase", IF(Table2[[#This Row],[Stock_After]]=Table2[[#This Row],[Stock_Before]]+Table2[[#This Row],[Quantity]], "OK", "Error"), IF(Table2[[#This Row],[Transaction_Type]]="Return", IF(Table2[[#This Row],[Stock_After]]=Table2[[#This Row],[Stock_Before]]+Table2[[#This Row],[Quantity]], "OK", "Error"), IF(Table2[[#This Row],[Transaction_Type]]="Sale", IF(Table2[[#This Row],[Stock_After]]=MAX(0, Table2[[#This Row],[Stock_Before]]-Table2[[#This Row],[Quantity]]), "OK", "Error"), IF(Table2[[#This Row],[Transaction_Type]]="Adjustment", IF(Table2[[#This Row],[Stock_After]]>=0, "OK", "Error"), "Check")))) -> OK | AC3: =IF(AND(Table2[[#This Row],[Quantity]]>=0,Table2[[#This Row],[Unit_Price]]>=0),"OK","Error") -> OK | AD3: =IF(Table2[[#This Row],[Stock_After]]=0,"Stock-Out",IF(Table2[[#This Row],[Stock_After]]<=10,"Low Stock","Healthy")) -> Healthy
A4: T00003 | B4: 46372 | C4: P004 | D4: Monitor | E4: Electronics | F4: Displays | G4: S014 | H4: W03 | I4: Adjustment | J4: 76 | K4: 18281 | L4: 1389356 | M4: 464 | N4: 388 | O4: E009 | Q4: Card | R4: Completed | S4: Regular Transaction | T4: =IF(COUNTIF(T6,Q16)>1,"Duplicate","OK") -> OK | U4: =IF(Table2[[#This Row],[Transaction_ID]]="","Missing","OK") -> OK | V4: =IF(COUNTIF(Table2[[#This Row],[Product_ID]],Table2[[#This Row],[Product_ID]])=0,"Invalid Product","OK") -> OK | W4: =IF(COUNTIF(Table2[[#This Row],[Supplier_ID]],Table2[[#This Row],[Supplier_ID]])=0,"Invalid Supplier","OK") -> OK | X4: =IF(COUNTIF(Table2[[#This Row],[Warehouse_ID]],Table2[[#This Row],[Warehouse_ID]])=0,"Invalid Warehouse","OK") -> OK | Y4: =IF(COUNTIF(Table2[[#This Row],[Employee_ID]],Table2[[#This Row],[Employee_ID]])=0,"Invalid Employee","OK") -> OK | Z4: =IF(Table2[[#This Row],[Stock_After]]=Table2[[#This Row],[Stock_After]]+Table2[[#This Row],[Stock_After]]-Table2[[#This Row],[Stock_After]]-Table2[[#This Row],[Stock_After]]+Table2[[#This Row],[Stock_After]],"OK","Error") -> OK | AA4: =IF(ROUND(Table2[[#This Row],[Total_Value]],2)=ROUND(Table2[[#This Row],[Quantity]]*Table2[[#This Row],[Unit_Price]],2),"OK","Error") -> OK | AB4: =IF(Table2[[#This Row],[Transaction_Type]]="Purchase", IF(Table2[[#This Row],[Stock_After]]=Table2[[#This Row],[Stock_Before]]+Table2[[#This Row],[Quantity]], "OK", "Error"), IF(Table2[[#This Row],[Transaction_Type]]="Return", IF(Table2[[#This Row],[Stock_After]]=Table2[[#This Row],[Stock_Before]]+Table2[[#This Row],[Quantity]], "OK", "Error"), IF(Table2[[#This Row],[Transaction_Type]]="Sale", IF(Table2[[#This Row],[Stock_After]]=MAX(0, Table2[[#This Row],[Stock_Before]]-Table2[[#This Row],[Quantity]]), "OK", "Error"), IF(Table2[[#This Row],[Transaction_Type]]="Adjustment", IF(Table2[[#This Row],[Stock_After]]>=0, "OK", "Error"), "Check")))) -> OK | AC4: =IF(AND(Table2[[#This Row],[Quantity]]>=0,Table2[[#This Row],[Unit_Price]]>=0),"OK","Error") -> OK | AD4: =IF(Table2[[#This Row],[Stock_After]]=0,"Stock-Out",IF(Table2[[#This Row],[Stock_After]]<=10,"Low Stock","Healthy")) -> Healthy
A5: T00004 | B5: 46025 | C5: P004 | D5: Monitor | E5: Electronics | F5: Displays | G5: S012 | H5: W05 | I5: Return | J5: 14 | K5: 6128 | L5: 85792 | M5: 244 | N5: 258 | O5: E009 | Q5: Cash | R5: Completed | S5: Regular Transaction | T5: =IF(COUNTIF(T7,Q17)>1,"Duplicate","OK") -> OK | U5: =IF(Table2[[#This Row],[Transaction_ID]]="","Missing","OK") -> OK | V5: =IF(COUNTIF(Table2[[#This Row],[Product_ID]],Table2[[#This Row],[Product_ID]])=0,"Invalid Product","OK") -> OK | W5: =IF(COUNTIF(Table2[[#This Row],[Supplier_ID]],Table2[[#This Row],[Supplier_ID]])=0,"Invalid Supplier","OK") -> OK | X5: =IF(COUNTIF(Table2[[#This Row],[Warehouse_ID]],Table2[[#This Row],[Warehouse_ID]])=0,"Invalid Warehouse","OK") -> OK | Y5: =IF(COUNTIF(Table2[[#This Row],[Employee_ID]],Table2[[#This Row],[Employee_ID]])=0,"Invalid Employee","OK") -> OK | Z5: =IF(Table2[[#This Row],[Stock_After]]=Table2[[#This Row],[Stock_After]]+Table2[[#This Row],[Stock_After]]-Table2[[#This Row],[Stock_After]]-Table2[[#This Row],[Stock_After]]+Table2[[#This Row],[Stock_After]],"OK","Error") -> OK | AA5: =IF(ROUND(Table2[[#This Row],[Total_Value]],2)=ROUND(Table2[[#This Row],[Quantity]]*Table2[[#This Row],[Unit_Price]],2),"OK","Error") -> OK | AB5: =IF(Table2[[#This Row],[Transaction_Type]]="Purchase", IF(Table2[[#This Row],[Stock_After]]=Table2[[#This Row],[Stock_Before]]+Table2[[#This Row],[Quantity]], "OK", "Error"), IF(Table2[[#This Row],[Transaction_Type]]="Return", IF(Table2[[#This Row],[Stock_After]]=Table2[[#This Row],[Stock_Before]]+Table2[[#This Row],[Quantity]], "OK", "Error"), IF(Table2[[#This Row],[Transaction_Type]]="Sale", IF(Table2[[#This Row],[Stock_After]]=MAX(0, Table2[[#This Row],[Stock_Before]]-Table2[[#This Row],[Quantity]]), "OK", "Error"), IF(Table2[[#This Row],[Transaction_Type]]="Adjustment", IF(Table2[[#This Row],[Stock_After]]>=0, "OK", "Error"), "Check")))) -> OK | AC5: =IF(AND(Table2[[#This Row],[Quantity]]>=0,Table2[[#This Row],[Unit_Price]]>=0),"OK","Error") -> OK | AD5: =IF(Table2[[#This Row],[Stock_After]]=0,"Stock-Out",IF(Table2[[#This Row],[Stock_After]]<=10,"Low Stock","Healthy")) -> Healthy
A6: T00005 | B6: 46301 | C6: P008 | D6: Notebook | E6: Stationery | F6: Books | G6: S020 | H6: W03 | I6: Purchase | J6: 49 | K6: 5214 | L6: 255486 | M6: 332 | N6: 381 | O6: E019 | Q6: Card | R6: Approved | S6: Regular Transaction | T6: =IF(COUNTIF(T8,Q18)>1,"Duplicate","OK") -> OK | U6: =IF(Table2[[#This Row],[Transaction_ID]]="","Missing","OK") -> OK | V6: =IF(COUNTIF(Table2[[#This Row],[Product_ID]],Table2[[#This Row],[Product_ID]])=0,"Invalid Product","OK") -> OK | W6: =IF(COUNTIF(Table2[[#This Row],[Supplier_ID]],Table2[[#This Row],[Supplier_ID]])=0,"Invalid Supplier","OK") -> OK | X6: =IF(COUNTIF(Table2[[#This Row],[Warehouse_ID]],Table2[[#This Row],[Warehouse_ID]])=0,"Invalid Warehouse","OK") -> OK | Y6: =IF(COUNTIF(Table2[[#This Row],[Employee_ID]],Table2[[#This Row],[Employee_ID]])=0,"Invalid Employee","OK") -> OK | Z6: =IF(Table2[[#This Row],[Stock_After]]=Table2[[#This Row],[Stock_After]]+Table2[[#This Row],[Stock_After]]-Table2[[#This Row],[Stock_After]]-Table2[[#This Row],[Stock_After]]+Table2[[#This Row],[Stock_After]],"OK","Error") -> OK | AA6: =IF(ROUND(Table2[[#This Row],[Total_Value]],2)=ROUND(Table2[[#This Row],[Quantity]]*Table2[[#This Row],[Unit_Price]],2),"OK","Error") -> OK | AB6: =IF(Table2[[#This Row],[Transaction_Type]]="Purchase", IF(Table2[[#This Row],[Stock_After]]=Table2[[#This Row],[Stock_Before]]+Table2[[#This Row],[Quantity]], "OK", "Error"), IF(Table2[[#This Row],[Transaction_Type]]="Return", IF(Table2[[#This Row],[Stock_After]]=Table2[[#This Row],[Stock_Before]]+Table2[[#This Row],[Quantity]], "OK", "Error"), IF(Table2[[#This Row],[Transaction_Type]]="Sale", IF(Table2[[#This Row],[Stock_After]]=MAX(0, Table2[[#This Row],[Stock_Before]]-Table2[[#This Row],[Quantity]]), "OK", "Error"), IF(Table2[[#This Row],[Transaction_Type]]="Adjustment", IF(Table2[[#This Row],[Stock_After]]>=0, "OK", "Error"), "Check")))) -> OK | AC6: =IF(AND(Table2[[#This Row],[Quantity]]>=0,Table2[[#This Row],[Unit_Price]]>=0),"OK","Error") -> OK | AD6: =IF(Table2[[#This Row],[Stock_After]]=0,"Stock-Out",IF(Table2[[#This Row],[Stock_After]]<=10,"Low Stock","Healthy")) -> Healthy
A7: T00006 | B7: 45739 | C7: P002 | D7: Keyboard | E7: Electronics | F7: Accessories | G7: S008 | H7: W01 | I7: Purchase | J7: 85 | K7: 14985 | L7: 1273725 | M7: 445 | N7: 530 | O7: E013 | Q7: UPI | R7: Approved | S7: Regular Transaction | T7: =IF(COUNTIF(T9,Q19)>1,"Duplicate","OK") -> OK | U7: =IF(Table2[[#This Row],[Transaction_ID]]="","Missing","OK") -> OK | V7: =IF(COUNTIF(Table2[[#This Row],[Product_ID]],Table2[[#This Row],[Product_ID]])=0,"Invalid Product","OK") -> OK | W7: =IF(COUNTIF(Table2[[#This Row],[Supplier_ID]],Table2[[#This Row],[Supplier_ID]])=0,"Invalid Supplier","OK") -> OK | X7: =IF(COUNTIF(Table2[[#This Row],[Warehouse_ID]],Table2[[#This Row],[Warehouse_ID]])=0,"Invalid Warehouse","OK") -> OK | Y7: =IF(COUNTIF(Table2[[#This Row],[Employee_ID]],Table2[[#This Row],[Employee_ID]])=0,"Invalid Employee","OK") -> OK | Z7: =IF(Table2[[#This Row],[Stock_After]]=Table2[[#This Row],[Stock_After]]+Table2[[#This Row],[Stock_After]]-Table2[[#This Row],[Stock_After]]-Table2[[#This Row],[Stock_After]]+Table2[[#This Row],[Stock_After]],"OK","Error") -> OK | AA7: =IF(ROUND(Table2[[#This Row],[Total_Value]],2)=ROUND(Table2[[#This Row],[Quantity]]*Table2[[#This Row],[Unit_Price]],2),"OK","Error") -> OK | AB7: =IF(Table2[[#This Row],[Transaction_Type]]="Purchase", IF(Table2[[#This Row],[Stock_After]]=Table2[[#This Row],[Stock_Before]]+Table2[[#This Row],[Quantity]], "OK", "Error"), IF(Table2[[#This Row],[Transaction_Type]]="Return", IF(Table2[[#This Row],[Stock_After]]=Table2[[#This Row],[Stock_Before]]+Table2[[#This Row],[Quantity]], "OK", "Error"), IF(Table2[[#This Row],[Transaction_Type]]="Sale", IF(Table2[[#This Row],[Stock_After]]=MAX(0, Table2[[#This Row],[Stock_Before]]-Table2[[#This Row],[Quantity]]), "OK", "Error"), IF(Table2[[#This Row],[Transaction_Type]]="Adjustment", IF(Table2[[#This Row],[Stock_After]]>=0, "OK", "Error"), "Check")))) -> OK | AC7: =IF(AND(Table2[[#This Row],[Quantity]]>=0,Table2[[#This Row],[Unit_Price]]>=0),"OK","Error") -> OK | AD7: =IF(Table2[[#This Row],[Stock_After]]=0,"Stock-Out",IF(Table2[[#This Row],[Stock_After]]<=10,"Low Stock","Healthy")) -> Healthy
A8: T00007 | B8: 46344 | C8: P008 | D8: Notebook | E8: Stationery | F8: Books | G8: S009 | H8: W01 | I8: Return | J8: 21 | K8: 24310 | L8: 510510 | M8: 231 | N8: 252 | O8: E020 | Q8: Card | R8: Completed | S8: Regular Transaction | T8: =IF(COUNTIF(T10,Q20)>1,"Duplicate","OK") -> OK | U8: =IF(Table2[[#This Row],[Transaction_ID]]="","Missing","OK") -> OK | V8: =IF(COUNTIF(Table2[[#This Row],[Product_ID]],Table2[[#This Row],[Product_ID]])=0,"Invalid Product","OK") -> OK | W8: =IF(COUNTIF(Table2[[#This Row],[Supplier_ID]],Table2[[#This Row],[Supplier_ID]])=0,"Invalid Supplier","OK") -> OK | X8: =IF(COUNTIF(Table2[[#This Row],[Warehouse_ID]],Table2[[#This Row],[Warehouse_ID]])=0,"Invalid Warehouse","OK") -> OK | Y8: =IF(COUNTIF(Table2[[#This Row],[Employee_ID]],Table2[[#This Row],[Employee_ID]])=0,"Invalid Employee","OK") -> OK | Z8: =IF(Table2[[#This Row],[Stock_After]]=Table2[[#This Row],[Stock_After]]+Table2[[#This Row],[Stock_After]]-Table2[[#This Row],[Stock_After]]-Table2[[#This Row],[Stock_After]]+Table2[[#This Row],[Stock_After]],"OK","Error") -> OK | AA8: =IF(ROUND(Table2[[#This Row],[Total_Value]],2)=ROUND(Table2[[#This Row],[Quantity]]*Table2[[#This Row],[Unit_Price]],2),"OK","Error") -> OK | AB8: =IF(Table2[[#This Row],[Transaction_Type]]="Purchase", IF(Table2[[#This Row],[Stock_After]]=Table2[[#This Row],[Stock_Before]]+Table2[[#This Row],[Quantity]], "OK", "Error"), IF(Table2[[#This Row],[Transaction_Type]]="Return", IF(Table2[[#This Row],[Stock_After]]=Table2[[#This Row],[Stock_Before]]+Table2[[#This Row],[Quantity]], "OK", "Error"), IF(Table2[[#This Row],[Transaction_Type]]="Sale", IF(Table2[[#This Row],[Stock_After]]=MAX(0, Table2[[#This Row],[Stock_Before]]-Table2[[#This Row],[Quantity]]), "OK", "Error"), IF(Table2[[#This Row],[Transaction_Type]]="Adjustment", IF(Table2[[#This Row],[Stock_After]]>=0, "OK", "Error"), "Check")))) -> OK | AC8: =IF(AND(Table2[[#This Row],[Quantity]]>=0,Table2[[#This Row],[Unit_Price]]>=0),"OK","Error") -> OK | AD8: =IF(Table2[[#This Row],[Stock_After]]=0,"Stock-Out",IF(Table2[[#This Row],[Stock_After]]<=10,"Low Stock","Healthy")) -> Healthy
A9: T00008 | B9: 46362 | C9: P009 | D9: Pen | E9: Stationery | F9: Writing | G9: S018 | H9: W02 | I9: Sale | J9: 21 | K9: 30344 | L9: 637224 | M9: 244 | N9: 223 | O9: E011 | P9: C0139 | Q9: Cash | R9: Pending | S9: Regular Transaction | T9: =IF(COUNTIF(T11,Q21)>1,"Duplicate","OK") -> OK | U9: =IF(Table2[[#This Row],[Transaction_ID]]="","Missing","OK") -> OK | V9: =IF(COUNTIF(Table2[[#This Row],[Product_ID]],Table2[[#This Row],[Product_ID]])=0,"Invalid Product","OK") -> OK | W9: =IF(COUNTIF(Table2[[#This Row],[Supplier_ID]],Table2[[#This Row],[Supplier_ID]])=0,"Invalid Supplier","OK") -> OK | X9: =IF(COUNTIF(Table2[[#This Row],[Warehouse_ID]],Table2[[#This Row],[Warehouse_ID]])=0,"Invalid Warehouse","OK") -> OK | Y9: =IF(COUNTIF(Table2[[#This Row],[Employee_ID]],Table2[[#This Row],[Employee_ID]])=0,"Invalid Employee","OK") -> OK | Z9: =IF(Table2[[#This Row],[Stock_After]]=Table2[[#This Row],[Stock_After]]+Table2[[#This Row],[Stock_After]]-Table2[[#This Row],[Stock_After]]-Table2[[#This Row],[Stock_After]]+Table2[[#This Row],[Stock_After]],"OK","Error") -> OK | AA9: =IF(ROUND(Table2[[#This Row],[Total_Value]],2)=ROUND(Table2[[#This Row],[Quantity]]*Table2[[#This Row],[Unit_Price]],2),"OK","Error") -> OK | AB9: =IF(Table2[[#This Row],[Transaction_Type]]="Purchase", IF(Table2[[#This Row],[Stock_After]]=Table2[[#This Row],[Stock_Before]]+Table2[[#This Row],[Quantity]], "OK", "Error"), IF(Table2[[#This Row],[Transaction_Type]]="Return", IF(Table2[[#This Row],[Stock_After]]=Table2[[#This Row],[Stock_Before]]+Table2[[#This Row],[Quantity]], "OK", "Error"), IF(Table2[[#This Row],[Transaction_Type]]="Sale", IF(Table2[[#This Row],[Stock_After]]=MAX(0, Table2[[#This Row],[Stock_Before]]-Table2[[#This Row],[Quantity]]), "OK", "Error"), IF(Table2[[#This Row],[Transaction_Type]]="Adjustment", IF(Table2[[#This Row],[Stock_After]]>=0, "OK", "Error"), "Check")))) -> OK | AC9: =IF(AND(Table2[[#This Row],[Quantity]]>=0,Table2[[#This Row],[Unit_Price]]>=0),"OK","Error") -> OK | AD9: =IF(Table2[[#This Row],[Stock_After]]=0,"Stock-Out",IF(Table2[[#This Row],[Stock_After]]<=10,"Low Stock","Healthy")) -> Healthy
A10: T00009 | B10: 45874 | C10: P004 | D10: Monitor | E10: Electronics | F10: Displays | G10: S019 | H10: W03 | I10: Purchase | J10: 41 | K10: 26340 | L10: 1079940 | M10: 187 | N10: 228 | O10: E007 | Q10: Credit | R10: Completed | S10: Regular Transaction | T10: =IF(COUNTIF(T12,Q22)>1,"Duplicate","OK") -> OK | U10: =IF(Table2[[#This Row],[Transaction_ID]]="","Missing","OK") -> OK | V10: =IF(COUNTIF(Table2[[#This Row],[Product_ID]],Table2[[#This Row],[Product_ID]])=0,"Invalid Product","OK") -> OK | W10: =IF(COUNTIF(Table2[[#This Row],[Supplier_ID]],Table2[[#This Row],[Supplier_ID]])=0,"Invalid Supplier","OK") -> OK | X10: =IF(COUNTIF(Table2[[#This Row],[Warehouse_ID]],Table2[[#This Row],[Warehouse_ID]])=0,"Invalid Warehouse","OK") -> OK | Y10: =IF(COUNTIF(Table2[[#This Row],[Employee_ID]],Table2[[#This Row],[Employee_ID]])=0,"Invalid Employee","OK") -> OK | Z10: =IF(Table2[[#This Row],[Stock_After]]=Table2[[#This Row],[Stock_After]]+Table2[[#This Row],[Stock_After]]-Table2[[#This Row],[Stock_After]]-Table2[[#This Row],[Stock_After]]+Table2[[#This Row],[Stock_After]],"OK","Error") -> OK | AA10: =IF(ROUND(Table2[[#This Row],[Total_Value]],2)=ROUND(Table2[[#This Row],[Quantity]]*Table2[[#This Row],[Unit_Price]],2),"OK","Error") -> OK | AB10: =IF(Table2[[#This Row],[Transaction_Type]]="Purchase", IF(Table2[[#This Row],[Stock_After]]=Table2[[#This Row],[Stock_Before]]+Table2[[#This Row],[Quantity]], "OK", "Error"), IF(Table2[[#This Row],[Transaction_Type]]="Return", IF(Table2[[#This Row],[Stock_After]]=Table2[[#This Row],[Stock_Before]]+Table2[[#This Row],[Quantity]], "OK", "Error"), IF(Table2[[#This Row],[Transaction_Type]]="Sale", IF(Table2[[#This Row],[Stock_After]]=MAX(0, Table2[[#This Row],[Stock_Before]]-Table2[[#This Row],[Quantity]]), "OK", "Error"), IF(Table2[[#This Row],[Transaction_Type]]="Adjustment", IF(Table2[[#This Row],[Stock_After]]>=0, "OK", "Error"), "Check")))) -> OK | AC10: =IF(AND(Table2[[#This Row],[Quantity]]>=0,Table2[[#This Row],[Unit_Price]]>=0),"OK","Error") -> OK | AD10: =IF(Table2[[#This Row],[Stock_After]]=0,"Stock-Out",IF(Table2[[#This Row],[Stock_After]]<=10,"Low Stock","Healthy")) -> Healthy
A11: T00010 | B11: 46232 | C11: P007 | D11: Office Desk | E11: Furniture | F11: Desks | G11: S018 | H11: W03 | I11: Adjustment | J11: 19 | K11: 17409 | L11: 330771 | M11: 121 | N11: 102 | O11: E019 | Q11: Credit | R11: Pending | S11: Regular Transaction | T11: =IF(COUNTIF(T13,Q23)>1,"Duplicate","OK") -> OK | U11: =IF(Table2[[#This Row],[Transaction_ID]]="","Missing","OK") -> OK | V11: =IF(COUNTIF(Table2[[#This Row],[Product_ID]],Table2[[#This Row],[Product_ID]])=0,"Invalid Product","OK") -> OK | W11: =IF(COUNTIF(Table2[[#This Row],[Supplier_ID]],Table2[[#This Row],[Supplier_ID]])=0,"Invalid Supplier","OK") -> OK | X11: =IF(COUNTIF(Table2[[#This Row],[Warehouse_ID]],Table2[[#This Row],[Warehouse_ID]])=0,"Invalid Warehouse","OK") -> OK | Y11: =IF(COUNTIF(Table2[[#This Row],[Employee_ID]],Table2[[#This Row],[Employee_ID]])=0,"Invalid Employee","OK") -> OK | Z11: =IF(Table2[[#This Row],[Stock_After]]=Table2[[#This Row],[Stock_After]]+Table2[[#This Row],[Stock_After]]-Table2[[#This Row],[Stock_After]]-Table2[[#This Row],[Stock_After]]+Table2[[#This Row],[Stock_After]],"OK","Error") -> OK | AA11: =IF(ROUND(Table2[[#This Row],[Total_Value]],2)=ROUND(Table2[[#This Row],[Quantity]]*Table2[[#This Row],[Unit_Price]],2),"OK","Error") -> OK | AB11: =IF(Table2[[#This Row],[Transaction_Type]]="Purchase", IF(Table2[[#This Row],[Stock_After]]=Table2[[#This Row],[Stock_Before]]+Table2[[#This Row],[Quantity]], "OK", "Error"), IF(Table2[[#This Row],[Transaction_Type]]="Return", IF(Table2[[#This Row],[Stock_After]]=Table2[[#This Row],[Stock_Before]]+Table2[[#This Row],[Quantity]], "OK", "Error"), IF(Table2[[#This Row],[Transaction_Type]]="Sale", IF(Table2[[#This Row],[Stock_After]]=MAX(0, Table2[[#This Row],[Stock_Before]]-Table2[[#This Row],[Quantity]]), "OK", "Error"), IF(Table2[[#This Row],[Transaction_Type]]="Adjustment", IF(Table2[[#This Row],[Stock_After]]>=0, "OK", "Error"), "Check")))) -> OK | AC11: =IF(AND(Table2[[#This Row],[Quantity]]>=0,Table2[[#This Row],[Unit_Price]]>=0),"OK","Error") -> OK | AD11: =IF(Table2[[#This Row],[Stock_After]]=0,"Stock-Out",IF(Table2[[#This Row],[Stock_After]]<=10,"Low Stock","Healthy")) -> Healthy
A12: T00011 | B12: 45706 | C12: P010 | D12: File Folder | E12: Stationery | F12: Files | G12: S004 | H12: W02 | I12: Adjustment | J12: 47 | K12: 14423 | L12: 677881 | M12: 120 | N12: 167 | O12: E006 | Q12: Credit | R12: Completed | S12: Regular Transaction | T12: =IF(COUNTIF(T14,Q24)>1,"Duplicate","OK") -> OK | U12: =IF(Table2[[#This Row],[Transaction_ID]]="","Missing","OK") -> OK | V12: =IF(COUNTIF(Table2[[#This Row],[Product_ID]],Table2[[#This Row],[Product_ID]])=0,"Invalid Product","OK") -> OK | W12: =IF(COUNTIF(Table2[[#This Row],[Supplier_ID]],Table2[[#This Row],[Supplier_ID]])=0,"Invalid Supplier","OK") -> OK | X12: =IF(COUNTIF(Table2[[#This Row],[Warehouse_ID]],Table2[[#This Row],[Warehouse_ID]])=0,"Invalid Warehouse","OK") -> OK | Y12: =IF(COUNTIF(Table2[[#This Row],[Employee_ID]],Table2[[#This Row],[Employee_ID]])=0,"Invalid Employee","OK") -> OK | Z12: =IF(Table2[[#This Row],[Stock_After]]=Table2[[#This Row],[Stock_After]]+Table2[[#This Row],[Stock_After]]-Table2[[#This Row],[Stock_After]]-Table2[[#This Row],[Stock_After]]+Table2[[#This Row],[Stock_After]],"OK","Error") -> OK | AA12: =IF(ROUND(Table2[[#This Row],[Total_Value]],2)=ROUND(Table2[[#This Row],[Quantity]]*Table2[[#This Row],[Unit_Price]],2),"OK","Error") -> OK | AB12: =IF(Table2[[#This Row],[Transaction_Type]]="Purchase", IF(Table2[[#This Row],[Stock_After]]=Table2[[#This Row],[Stock_Before]]+Table2[[#This Row],[Quantity]], "OK", "Error"), IF(Table2[[#This Row],[Transaction_Type]]="Return", IF(Table2[[#This Row],[Stock_After]]=Table2[[#This Row],[Stock_Before]]+Table2[[#This Row],[Quantity]], "OK", "Error"), IF(Table2[[#This Row],[Transaction_Type]]="Sale", IF(Table2[[#This Row],[Stock_After]]=MAX(0, Table2[[#This Row],[Stock_Before]]-Table2[[#This Row],[Quantity]]), "OK", "Error"), IF(Table2[[#This Row],[Transaction_Type]]="Adjustment", IF(Table2[[#This Row],[Stock_After]]>=0, "OK", "Error"), "Check")))) -> OK | AC12: =IF(AND(Table2[[#This Row],[Quantity]]>=0,Table2[[#This Row],[Unit_Price]]>=0),"OK","Error") -> OK | AD12: =IF(Table2[[#This Row],[Stock_After]]=0,"Stock-Out",IF(Table2[[#This Row],[Stock_After]]<=10,"Low Stock","Healthy")) -> Healthy
A13: T00012 | B13: 46199 | C13: P010 | D13: File Folder | E13: Stationery | F13: Files | G13: S009 | H13: W05 | I13: Purchase | J13: 50 | K13: 25059 | L13: 1252950 | M13: 355 | N13: 405 | O13: E001 | Q13: Cash | R13: Approved | S13: Regular Transaction | T13: =IF(COUNTIF(T15,Q25)>1,"Duplicate","OK") -> OK | U13: =IF(Table2[[#This Row],[Transaction_ID]]="","Missing","OK") -> OK | V13: =IF(COUNTIF(Table2[[#This Row],[Product_ID]],Table2[[#This Row],[Product_ID]])=0,"Invalid Product","OK") -> OK | W13: =IF(COUNTIF(Table2[[#This Row],[Supplier_ID]],Table2[[#This Row],[Supplier_ID]])=0,"Invalid Supplier","OK") -> OK | X13: =IF(COUNTIF(Table2[[#This Row],[Warehouse_ID]],Table2[[#This Row],[Warehouse_ID]])=0,"Invalid Warehouse","OK") -> OK | Y13: =IF(COUNTIF(Table2[[#This Row],[Employee_ID]],Table2[[#This Row],[Employee_ID]])=0,"Invalid Employee","OK") -> OK | Z13: =IF(Table2[[#This Row],[Stock_After]]=Table2[[#This Row],[Stock_After]]+Table2[[#This Row],[Stock_After]]-Table2[[#This Row],[Stock_After]]-Table2[[#This Row],[Stock_After]]+Table2[[#This Row],[Stock_After]],"OK","Error") -> OK | AA13: =IF(ROUND(Table2[[#This Row],[Total_Value]],2)=ROUND(Table2[[#This Row],[Quantity]]*Table2[[#This Row],[Unit_Price]],2),"OK","Error") -> OK | AB13: =IF(Table2[[#This Row],[Transaction_Type]]="Purchase", IF(Table2[[#This Row],[Stock_After]]=Table2[[#This Row],[Stock_Before]]+Table2[[#This Row],[Quantity]], "OK", "Error"), IF(Table2[[#This Row],[Transaction_Type]]="Return", IF(Table2[[#This Row],[Stock_After]]=Table2[[#This Row],[Stock_Before]]+Table2[[#This Row],[Quantity]], "OK", "Error"), IF(Table2[[#This Row],[Transaction_Type]]="Sale", IF(Table2[[#This Row],[Stock_After]]=MAX(0, Table2[[#This Row],[Stock_Before]]-Table2[[#This Row],[Quantity]]), "OK", "Error"), IF(Table2[[#This Row],[Transaction_Type]]="Adjustment", IF(Table2[[#This Row],[Stock_After]]>=0, "OK", "Error"), "Check")))) -> OK | AC13: =IF(AND(Table2[[#This Row],[Quantity]]>=0,Table2[[#This Row],[Unit_Price]]>=0),"OK","Error") -> OK | AD13: =IF(Table2[[#This Row],[Stock_After]]=0,"Stock-Out",IF(Table2[[#This Row],[Stock_After]]<=10,"Low Stock","Healthy")) -> Healthy
A14: T00013 | B14: 45958 | C14: P009 | D14: Pen | E14: Stationery | F14: Writing | G14: S014 | H14: W02 | I14: Return | J14: 99 | K14: 42056 | L14: 4163544 | M14: 224 | N14: 323 | O14: E015 | Q14: Cash | R14: Completed | S14: Regular Transaction | T14: =IF(COUNTIF(T16,Q26)>1,"Duplicate","OK") -> OK | U14: =IF(Table2[[#This Row],[Transaction_ID]]="","Missing","OK") -> OK | V14: =IF(COUNTIF(Table2[[#This Row],[Product_ID]],Table2[[#This Row],[Product_ID]])=0,"Invalid Product","OK") -> OK | W14: =IF(COUNTIF(Table2[[#This Row],[Supplier_ID]],Table2[[#This Row],[Supplier_ID]])=0,"Invalid Supplier","OK") -> OK | X14: =IF(COUNTIF(Table2[[#This Row],[Warehouse_ID]],Table2[[#This Row],[Warehouse_ID]])=0,"Invalid Warehouse","OK") -> OK | Y14: =IF(COUNTIF(Table2[[#This Row],[Employee_ID]],Table2[[#This Row],[Employee_ID]])=0,"Invalid Employee","OK") -> OK | Z14: =IF(Table2[[#This Row],[Stock_After]]=Table2[[#This Row],[Stock_After]]+Table2[[#This Row],[Stock_After]]-Table2[[#This Row],[Stock_After]]-Table2[[#This Row],[Stock_After]]+Table2[[#This Row],[Stock_After]],"OK","Error") -> OK | AA14: =IF(ROUND(Table2[[#This Row],[Total_Value]],2)=ROUND(Table2[[#This Row],[Quantity]]*Table2[[#This Row],[Unit_Price]],2),"OK","Error") -> OK | AB14: =IF(Table2[[#This Row],[Transaction_Type]]="Purchase", IF(Table2[[#This Row],[Stock_After]]=Table2[[#This Row],[Stock_Before]]+Table2[[#This Row],[Quantity]], "OK", "Error"), IF(Table2[[#This Row],[Transaction_Type]]="Return", IF(Table2[[#This Row],[Stock_After]]=Table2[[#This Row],[Stock_Before]]+Table2[[#This Row],[Quantity]], "OK", "Error"), IF(Table2[[#This Row],[Transaction_Type]]="Sale", IF(Table2[[#This Row],[Stock_After]]=MAX(0, Table2[[#This Row],[Stock_Before]]-Table2[[#This Row],[Quantity]]), "OK", "Error"), IF(Table2[[#This Row],[Transaction_Type]]="Adjustment", IF(Table2[[#This Row],[Stock_After]]>=0, "OK", "Error"), "Check")))) -> OK | AC14: =IF(AND(Table2[[#This Row],[Quantity]]>=0,Table2[[#This Row],[Unit_Price]]>=0),"OK","Error") -> OK | AD14: =IF(Table2[[#This Row],[Stock_After]]=0,"Stock-Out",IF(Table2[[#This Row],[Stock_After]]<=10,"Low Stock","Healthy")) -> Healthy
A15: T00014 | B15: 46312 | C15: P005 | D15: Printer | E15: Electronics | F15: Printers | G15: S017 | H15: W05 | I15: Sale | J15: 65 | K15: 7023 | L15: 456495 | M15: 495 | N15: 430 | O15: E007 | P15: C0321 | Q15: Card | R15: Approved | S15: Regular Transaction | T15: =IF(COUNTIF(T17,Q27)>1,"Duplicate","OK") -> OK | U15: =IF(Table2[[#This Row],[Transaction_ID]]="","Missing","OK") -> OK | V15: =IF(COUNTIF(Table2[[#This Row],[Product_ID]],Table2[[#This Row],[Product_ID]])=0,"Invalid Product","OK") -> OK | W15: =IF(COUNTIF(Table2[[#This Row],[Supplier_ID]],Table2[[#This Row],[Supplier_ID]])=0,"Invalid Supplier","OK") -> OK | X15: =IF(COUNTIF(Table2[[#This Row],[Warehouse_ID]],Table2[[#This Row],[Warehouse_ID]])=0,"Invalid Warehouse","OK") -> OK | Y15: =IF(COUNTIF(Table2[[#This Row],[Employee_ID]],Table2[[#This Row],[Employee_ID]])=0,"Invalid Employee","OK") -> OK | Z15: =IF(Table2[[#This Row],[Stock_After]]=Table2[[#This Row],[Stock_After]]+Table2[[#This Row],[Stock_After]]-Table2[[#This Row],[Stock_After]]-Table2[[#This Row],[Stock_After]]+Table2[[#This Row],[Stock_After]],"OK","Error") -> OK | AA15: =IF(ROUND(Table2[[#This Row],[Total_Value]],2)=ROUND(Table2[[#This Row],[Quantity]]*Table2[[#This Row],[Unit_Price]],2),"OK","Error") -> OK | AB15: =IF(Table2[[#This Row],[Transaction_Type]]="Purchase", IF(Table2[[#This Row],[Stock_After]]=Table2[[#This Row],[Stock_Before]]+Table2[[#This Row],[Quantity]], "OK", "Error"), IF(Table2[[#This Row],[Transaction_Type]]="Return", IF(Table2[[#This Row],[Stock_After]]=Table2[[#This Row],[Stock_Before]]+Table2[[#This Row],[Quantity]], "OK", "Error"), IF(Table2[[#This Row],[Transaction_Type]]="Sale", IF(Table2[[#This Row],[Stock_After]]=MAX(0, Table2[[#This Row],[Stock_Before]]-Table2[[#This Row],[Quantity]]), "OK", "Error"), IF(Table2[[#This Row],[Transaction_Type]]="Adjustment", IF(Table2[[#This Row],[Stock_After]]>=0, "OK", "Error"), "Check")))) -> OK | AC15: =IF(AND(Table2[[#This Row],[Quantity]]>=0,Table2[[#This Row],[Unit_Price]]>=0),"OK","Error") -> OK | AD15: =IF(Table2[[#This Row],[Stock_After]]=0,"Stock-Out",IF(Table2[[#This Row],[Stock_After]]<=10,"Low Stock","Healthy")) -> Healthy
A16: T00015 | B16: 46158 | C16: P006 | D16: Office Chair | E16: Furniture | F16: Chairs | G16: S001 | H16: W01 | I16: Sale | J16: 70 | K16: 34807 | L16: 2436490 | M16: 50 | N16: 0 | O16: E012 | P16: C0307 | Q16: UPI | R16: Approved | S16: Regular Transaction | T16: =IF(COUNTIF(T18,Q28)>1,"Duplicate","OK") -> OK | U16: =IF(Table2[[#This Row],[Transaction_ID]]="","Missing","OK") -> OK | V16: =IF(COUNTIF(Table2[[#This Row],[Product_ID]],Table2[[#This Row],[Product_ID]])=0,"Invalid Product","OK") -> OK | W16: =IF(COUNTIF(Table2[[#This Row],[Supplier_ID]],Table2[[#This Row],[Supplier_ID]])=0,"Invalid Supplier","OK") -> OK | X16: =IF(COUNTIF(Table2[[#This Row],[Warehouse_ID]],Table2[[#This Row],[Warehouse_ID]])=0,"Invalid Warehouse","OK") -> OK | Y16: =IF(COUNTIF(Table2[[#This Row],[Employee_ID]],Table2[[#This Row],[Employee_ID]])=0,"Invalid Employee","OK") -> OK | Z16: =IF(Table2[[#This Row],[Stock_After]]=Table2[[#This Row],[Stock_After]]+Table2[[#This Row],[Stock_After]]-Table2[[#This Row],[Stock_After]]-Table2[[#This Row],[Stock_After]]+Table2[[#This Row],[Stock_After]],"OK","Error") -> OK | AA16: =IF(ROUND(Table2[[#This Row],[Total_Value]],2)=ROUND(Table2[[#This Row],[Quantity]]*Table2[[#This Row],[Unit_Price]],2),"OK","Error") -> OK | AB16: =IF(Table2[[#This Row],[Transaction_Type]]="Purchase", IF(Table2[[#This Row],[Stock_After]]=Table2[[#This Row],[Stock_Before]]+Table2[[#This Row],[Quantity]], "OK", "Error"), IF(Table2[[#This Row],[Transaction_Type]]="Return", IF(Table2[[#This Row],[Stock_After]]=Table2[[#This Row],[Stock_Before]]+Table2[[#This Row],[Quantity]], "OK", "Error"), IF(Table2[[#This Row],[Transaction_Type]]="Sale", IF(Table2[[#This Row],[Stock_After]]=MAX(0, Table2[[#This Row],[Stock_Before]]-Table2[[#This Row],[Quantity]]), "OK", "Error"), IF(Table2[[#This Row],[Transaction_Type]]="Adjustment", IF(Table2[[#This Row],[Stock_After]]>=0, "OK", "Error"), "Check")))) -> OK | AC16: =IF(AND(Table2[[#This Row],[Quantity]]>=0,Table2[[#This Row],[Unit_Price]]>=0),"OK","Error") -> OK | AD16: =IF(Table2[[#This Row],[Stock_After]]=0,"Stock-Out",IF(Table2[[#This Row],[Stock_After]]<=10,"Low Stock","Healthy")) -> Stock-Out
A17: T00016 | B17: 46155 | C17: P004 | D17: Monitor | E17: Electronics | F17: Displays | G17: S003 | H17: W05 | I17: Purchase | J17: 31 | K17: 37232 | L17: 1154192 | M17: 90 | N17: 121 | O17: E005 | Q17: Card | R17: Completed | S17: Regular Transaction | T17: =IF(COUNTIF(T19,Q29)>1,"Duplicate","OK") -> OK | U17: =IF(Table2[[#This Row],[Transaction_ID]]="","Missing","OK") -> OK | V17: =IF(COUNTIF(Table2[[#This Row],[Product_ID]],Table2[[#This Row],[Product_ID]])=0,"Invalid Product","OK") -> OK | W17: =IF(COUNTIF(Table2[[#This Row],[Supplier_ID]],Table2[[#This Row],[Supplier_ID]])=0,"Invalid Supplier","OK") -> OK | X17: =IF(COUNTIF(Table2[[#This Row],[Warehouse_ID]],Table2[[#This Row],[Warehouse_ID]])=0,"Invalid Warehouse","OK") -> OK | Y17: =IF(COUNTIF(Table2[[#This Row],[Employee_ID]],Table2[[#This Row],[Employee_ID]])=0,"Invalid Employee","OK") -> OK | Z17: =IF(Table2[[#This Row],[Stock_After]]=Table2[[#This Row],[Stock_After]]+Table2[[#This Row],[Stock_After]]-Table2[[#This Row],[Stock_After]]-Table2[[#This Row],[Stock_After]]+Table2[[#This Row],[Stock_After]],"OK","Error") -> OK | AA17: =IF(ROUND(Table2[[#This Row],[Total_Value]],2)=ROUND(Table2[[#This Row],[Quantity]]*Table2[[#This Row],[Unit_Price]],2),"OK","Error") -> OK | AB17: =IF(Table2[[#This Row],[Transaction_Type]]="Purchase", IF(Table2[[#This Row],[Stock_After]]=Table2[[#This Row],[Stock_Before]]+Table2[[#This Row],[Quantity]], "OK", "Error"), IF(Table2[[#This Row],[Transaction_Type]]="Return", IF(Table2[[#This Row],[Stock_After]]=Table2[[#This Row],[Stock_Before]]+Table2[[#This Row],[Quantity]], "OK", "Error"), IF(Table2[[#This Row],[Transaction_Type]]="Sale", IF(Table2[[#This Row],[Stock_After]]=MAX(0, Table2[[#This Row],[Stock_Before]]-Table2[[#This Row],[Quantity]]), "OK", "Error"), IF(Table2[[#This Row],[Transaction_Type]]="Adjustment", IF(Table2[[#This Row],[Stock_After]]>=0, "OK", "Error"), "Check")))) -> OK | AC17: =IF(AND(Table2[[#This Row],[Quantity]]>=0,Table2[[#This Row],[Unit_Price]]>=0),"OK","Error") -> OK | AD17: =IF(Table2[[#This Row],[Stock_After]]=0,"Stock-Out",IF(Table2[[#This Row],[Stock_After]]<=10,"Low Stock","Healthy")) -> Healthy
A18: T00017 | B18: 45874 | C18: P008 | D18: Notebook | E18: Stationery | F18: Books | G18: S018 | H18: W02 | I18: Sale | J18: 34 | K18: 34631 | L18: 1177454 | M18: 496 | N18: 462 | O18: E010 | P18: C0311 | Q18: Credit | R18: Approved | S18: Regular Transaction | T18: =IF(COUNTIF(T20,Q30)>1,"Duplicate","OK") -> OK | U18: =IF(Table2[[#This Row],[Transaction_ID]]="","Missing","OK") -> OK | V18: =IF(COUNTIF(Table2[[#This Row],[Product_ID]],Table2[[#This Row],[Product_ID]])=0,"Invalid Product","OK") -> OK | W18: =IF(COUNTIF(Table2[[#This Row],[Supplier_ID]],Table2[[#This Row],[Supplier_ID]])=0,"Invalid Supplier","OK") -> OK | X18: =IF(COUNTIF(Table2[[#This Row],[Warehouse_ID]],Table2[[#This Row],[Warehouse_ID]])=0,"Invalid Warehouse","OK") -> OK | Y18: =IF(COUNTIF(Table2[[#This Row],[Employee_ID]],Table2[[#This Row],[Employee_ID]])=0,"Invalid Employee","OK") -> OK | Z18: =IF(Table2[[#This Row],[Stock_After]]=Table2[[#This Row],[Stock_After]]+Table2[[#This Row],[Stock_After]]-Table2[[#This Row],[Stock_After]]-Table2[[#This Row],[Stock_After]]+Table2[[#This Row],[Stock_After]],"OK","Error") -> OK | AA18: =IF(ROUND(Table2[[#This Row],[Total_Value]],2)=ROUND(Table2[[#This Row],[Quantity]]*Table2[[#This Row],[Unit_Price]],2),"OK","Error") -> OK | AB18: =IF(Table2[[#This Row],[Transaction_Type]]="Purchase", IF(Table2[[#This Row],[Stock_After]]=Table2[[#This Row],[Stock_Before]]+Table2[[#This Row],[Quantity]], "OK", "Error"), IF(Table2[[#This Row],[Transaction_Type]]="Return", IF(Table2[[#This Row],[Stock_After]]=Table2[[#This Row],[Stock_Before]]+Table2[[#This Row],[Quantity]], "OK", "Error"), IF(Table2[[#This Row],[Transaction_Type]]="Sale", IF(Table2[[#This Row],[Stock_After]]=MAX(0, Table2[[#This Row],[Stock_Before]]-Table2[[#This Row],[Quantity]]), "OK", "Error"), IF(Table2[[#This Row],[Transaction_Type]]="Adjustment", IF(Table2[[#This Row],[Stock_After]]>=0, "OK", "Error"), "Check")))) -> OK | AC18: =IF(AND(Table2[[#This Row],[Quantity]]>=0,Table2[[#This Row],[Unit_Price]]>=0),"OK","Error") -> OK | AD18: =IF(Table2[[#This Row],[Stock_After]]=0,"Stock-Out",IF(Table2[[#This Row],[Stock_After]]<=10,"Low Stock","Healthy")) -> Healthy
A19: T00018 | B19: 45723 | C19: P006 | D19: Office Chair | E19: Furniture | F19: Chairs | G19: S011 | H19: W01 | I19: Adjustment | J19: 67 | K19: 29638 | L19: 1985746 | M19: 111 | N19: 44 | O19: E019 | Q19: Card | R19: Completed | S19: Regular Transaction | T19: =IF(COUNTIF(T21,Q31)>1,"Duplicate","OK") -> OK | U19: =IF(Table2[[#This Row],[Transaction_ID]]="","Missing","OK") -> OK | V19: =IF(COUNTIF(Table2[[#This Row],[Product_ID]],Table2[[#This Row],[Product_ID]])=0,"Invalid Product","OK") -> OK | W19: =IF(COUNTIF(Table2[[#This Row],[Supplier_ID]],Table2[[#This Row],[Supplier_ID]])=0,"Invalid Supplier","OK") -> OK | X19: =IF(COUNTIF(Table2[[#This Row],[Warehouse_ID]],Table2[[#This Row],[Warehouse_ID]])=0,"Invalid Warehouse","OK") -> OK | Y19: =IF(COUNTIF(Table2[[#This Row],[Employee_ID]],Table2[[#This Row],[Employee_ID]])=0,"Invalid Employee","OK") -> OK | Z19: =IF(Table2[[#This Row],[Stock_After]]=Table2[[#This Row],[Stock_After]]+Table2[[#This Row],[Stock_After]]-Table2[[#This Row],[Stock_After]]-Table2[[#This Row],[Stock_After]]+Table2[[#This Row],[Stock_After]],"OK","Error") -> OK | AA19: =IF(ROUND(Table2[[#This Row],[Total_Value]],2)=ROUND(Table2[[#This Row],[Quantity]]*Table2[[#This Row],[Unit_Price]],2),"OK","Error") -> OK | AB19: =IF(Table2[[#This Row],[Transaction_Type]]="Purchase", IF(Table2[[#This Row],[Stock_After]]=Table2[[#This Row],[Stock_Before]]+Table2[[#This Row],[Quantity]], "OK", "Error"), IF(Table2[[#This Row],[Transaction_Type]]="Return", IF(Table2[[#This Row],[Stock_After]]=Table2[[#This Row],[Stock_Before]]+Table2[[#This Row],[Quantity]], "OK", "Error"), IF(Table2[[#This Row],[Transaction_Type]]="Sale", IF(Table2[[#This Row],[Stock_After]]=MAX(0, Table2[[#This Row],[Stock_Before]]-Table2[[#This Row],[Quantity]]), "OK", "Error"), IF(Table2[[#This Row],[Transaction_Type]]="Adjustment", IF(Table2[[#This Row],[Stock_After]]>=0, "OK", "Error"), "Check")))) -> OK | AC19: =IF(AND(Table2[[#This Row],[Quantity]]>=0,Table2[[#This Row],[Unit_Price]]>=0),"OK","Error") -> OK | AD19: =IF(Table2[[#This Row],[Stock_After]]=0,"Stock-Out",IF(Table2[[#This Row],[Stock_After]]<=10,"Low Stock","Healthy")) -> Healthy
A20: T00019 | B20: 45892 | C20: P010 | D20: File Folder | E20: Stationery | F20: Files | G20: S003 | H20: W01 | I20: Sale | J20: 1 | K20: 4702 | L20: 4702 | M20: 412 | N20: 411 | O20: E011 | P20: C0324 | Q20: Cash | R20: Completed | S20: Regular Transaction | T20: =IF(COUNTIF(T22,Q32)>1,"Duplicate","OK") -> OK | U20: =IF(Table2[[#This Row],[Transaction_ID]]="","Missing","OK") -> OK | V20: =IF(COUNTIF(Table2[[#This Row],[Product_ID]],Table2[[#This Row],[Product_ID]])=0,"Invalid Product","OK") -> OK | W20: =IF(COUNTIF(Table2[[#This Row],[Supplier_ID]],Table2[[#This Row],[Supplier_ID]])=0,"Invalid Supplier","OK") -> OK | X20: =IF(COUNTIF(Table2[[#This Row],[Warehouse_ID]],Table2[[#This Row],[Warehouse_ID]])=0,"Invalid Warehouse","OK") -> OK | Y20: =IF(COUNTIF(Table2[[#This Row],[Employee_ID]],Table2[[#This Row],[Employee_ID]])=0,"Invalid Employee","OK") -> OK | Z20: =IF(Table2[[#This Row],[Stock_After]]=Table2[[#This Row],[Stock_After]]+Table2[[#This Row],[Stock_After]]-Table2[[#This Row],[Stock_After]]-Table2[[#This Row],[Stock_After]]+Table2[[#This Row],[Stock_After]],"OK","Error") -> OK | AA20: =IF(ROUND(Table2[[#This Row],[Total_Value]],2)=ROUND(Table2[[#This Row],[Quantity]]*Table2[[#This Row],[Unit_Price]],2),"OK","Error") -> OK | AB20: =IF(Table2[[#This Row],[Transaction_Type]]="Purchase", IF(Table2[[#This Row],[Stock_After]]=Table2[[#This Row],[Stock_Before]]+Table2[[#This Row],[Quantity]], "OK", "Error"), IF(Table2[[#This Row],[Transaction_Type]]="Return", IF(Table2[[#This Row],[Stock_After]]=Table2[[#This Row],[Stock_Before]]+Table2[[#This Row],[Quantity]], "OK", "Error"), IF(Table2[[#This Row],[Transaction_Type]]="Sale", IF(Table2[[#This Row],[Stock_After]]=MAX(0, Table2[[#This Row],[Stock_Before]]-Table2[[#This Row],[Quantity]]), "OK", "Error"), IF(Table2[[#This Row],[Transaction_Type]]="Adjustment", IF(Table2[[#This Row],[Stock_After]]>=0, "OK", "Error"), "Check")))) -> OK | AC20: =IF(AND(Table2[[#This Row],[Quantity]]>=0,Table2[[#This Row],[Unit_Price]]>=0),"OK","Error") -> OK | AD20: =IF(Table2[[#This Row],[Stock_After]]=0,"Stock-Out",IF(Table2[[#This Row],[Stock_After]]<=10,"Low Stock","Healthy")) -> Healthy
A21: T00020 | B21: 45793 | C21: P009 | D21: Pen | E21: Stationery | F21: Writing | G21: S019 | H21: W05 | I21: Sale | J21: 36 | K21: 43892 | L21: 1580112 | M21: 298 | N21: 262 | O21: E016 | P21: C0110 | Q21: Card | R21: Pending | S21: Regular Transaction | T21: =IF(COUNTIF(T23,Q33)>1,"Duplicate","OK") -> OK | U21: =IF(Table2[[#This Row],[Transaction_ID]]="","Missing","OK") -> OK | V21: =IF(COUNTIF(Table2[[#This Row],[Product_ID]],Table2[[#This Row],[Product_ID]])=0,"Invalid Product","OK") -> OK | W21: =IF(COUNTIF(Table2[[#This Row],[Supplier_ID]],Table2[[#This Row],[Supplier_ID]])=0,"Invalid Supplier","OK") -> OK | X21: =IF(COUNTIF(Table2[[#This Row],[Warehouse_ID]],Table2[[#This Row],[Warehouse_ID]])=0,"Invalid Warehouse","OK") -> OK | Y21: =IF(COUNTIF(Table2[[#This Row],[Employee_ID]],Table2[[#This Row],[Employee_ID]])=0,"Invalid Employee","OK") -> OK | Z21: =IF(Table2[[#This Row],[Stock_After]]=Table2[[#This Row],[Stock_After]]+Table2[[#This Row],[Stock_After]]-Table2[[#This Row],[Stock_After]]-Table2[[#This Row],[Stock_After]]+Table2[[#This Row],[Stock_After]],"OK","Error") -> OK | AA21: =IF(ROUND(Table2[[#This Row],[Total_Value]],2)=ROUND(Table2[[#This Row],[Quantity]]*Table2[[#This Row],[Unit_Price]],2),"OK","Error") -> OK | AB21: =IF(Table2[[#This Row],[Transaction_Type]]="Purchase", IF(Table2[[#This Row],[Stock_After]]=Table2[[#This Row],[Stock_Before]]+Table2[[#This Row],[Quantity]], "OK", "Error"), IF(Table2[[#This Row],[Transaction_Type]]="Return", IF(Table2[[#This Row],[Stock_After]]=Table2[[#This Row],[Stock_Before]]+Table2[[#This Row],[Quantity]], "OK", "Error"), IF(Table2[[#This Row],[Transaction_Type]]="Sale", IF(Table2[[#This Row],[Stock_After]]=MAX(0, Table2[[#This Row],[Stock_Before]]-Table2[[#This Row],[Quantity]]), "OK", "Error"), IF(Table2[[#This Row],[Transaction_Type]]="Adjustment", IF(Table2[[#This Row],[Stock_After]]>=0, "OK", "Error"), "Check")))) -> OK | AC21: =IF(AND(Table2[[#This Row],[Quantity]]>=0,Table2[[#This Row],[Unit_Price]]>=0),"OK","Error") -> OK | AD21: =IF(Table2[[#This Row],[Stock_After]]=0,"Stock-Out",IF(Table2[[#This Row],[Stock_After]]<=10,"Low Stock","Healthy")) -> Healthy
A22: T00021 | B22: 46091 | C22: P008 | D22: Notebook | E22: Stationery | F22: Books | G22: S014 | H22: W04 | I22: Adjustment | J22: 25 | K22: 6231 | L22: 155775 | M22: 99 | N22: 124 | O22: E002 | Q22: Cash | R22: Approved | S22: Regular Transaction | T22: =IF(COUNTIF(T24,Q34)>1,"Duplicate","OK") -> OK | U22: =IF(Table2[[#This Row],[Transaction_ID]]="","Missing","OK") -> OK | V22: =IF(COUNTIF(Table2[[#This Row],[Product_ID]],Table2[[#This Row],[Product_ID]])=0,"Invalid Product","OK") -> OK | W22: =IF(COUNTIF(Table2[[#This Row],[Supplier_ID]],Table2[[#This Row],[Supplier_ID]])=0,"Invalid Supplier","OK") -> OK | X22: =IF(COUNTIF(Table2[[#This Row],[Warehouse_ID]],Table2[[#This Row],[Warehouse_ID]])=0,"Invalid Warehouse","OK") -> OK | Y22: =IF(COUNTIF(Table2[[#This Row],[Employee_ID]],Table2[[#This Row],[Employee_ID]])=0,"Invalid Employee","OK") -> OK | Z22: =IF(Table2[[#This Row],[Stock_After]]=Table2[[#This Row],[Stock_After]]+Table2[[#This Row],[Stock_After]]-Table2[[#This Row],[Stock_After]]-Table2[[#This Row],[Stock_After]]+Table2[[#This Row],[Stock_After]],"OK","Error") -> OK | AA22: =IF(ROUND(Table2[[#This Row],[Total_Value]],2)=ROUND(Table2[[#This Row],[Quantity]]*Table2[[#This Row],[Unit_Price]],2),"OK","Error") -> OK | AB22: =IF(Table2[[#This Row],[Transaction_Type]]="Purchase", IF(Table2[[#This Row],[Stock_After]]=Table2[[#This Row],[Stock_Before]]+Table2[[#This Row],[Quantity]], "OK", "Error"), IF(Table2[[#This Row],[Transaction_Type]]="Return", IF(Table2[[#This Row],[Stock_After]]=Table2[[#This Row],[Stock_Before]]+Table2[[#This Row],[Quantity]], "OK", "Error"), IF(Table2[[#This Row],[Transaction_Type]]="Sale", IF(Table2[[#This Row],[Stock_After]]=MAX(0, Table2[[#This Row],[Stock_Before]]-Table2[[#This Row],[Quantity]]), "OK", "Error"), IF(Table2[[#This Row],[Transaction_Type]]="Adjustment", IF(Table2[[#This Row],[Stock_After]]>=0, "OK", "Error"), "Check")))) -> OK | AC22: =IF(AND(Table2[[#This Row],[Quantity]]>=0,Table2[[#This Row],[Unit_Price]]>=0),"OK","Error") -> OK | AD22: =IF(Table2[[#This Row],[Stock_After]]=0,"Stock-Out",IF(Table2[[#This Row],[Stock_After]]<=10,"Low Stock","Healthy")) -> Healthy
A23: T00022 | B23: 45854 | C23: P001 | D23: Laptop | E23: Electronics | F23: Computers | G23: S007 | H23: W05 | I23: Adjustment | J23: 94 | K23: 22286 | L23: 2094884 | M23: 459 | N23: 365 | O23: E015 | Q23: Card | R23: Completed | S23: Regular Transaction | T23: =IF(COUNTIF(T25,Q35)>1,"Duplicate","OK") -> OK | U23: =IF(Table2[[#This Row],[Transaction_ID]]="","Missing","OK") -> OK | V23: =IF(COUNTIF(Table2[[#This Row],[Product_ID]],Table2[[#This Row],[Product_ID]])=0,"Invalid Product","OK") -> OK | W23: =IF(COUNTIF(Table2[[#This Row],[Supplier_ID]],Table2[[#This Row],[Supplier_ID]])=0,"Invalid Supplier","OK") -> OK | X23: =IF(COUNTIF(Table2[[#This Row],[Warehouse_ID]],Table2[[#This Row],[Warehouse_ID]])=0,"Invalid Warehouse","OK") -> OK | Y23: =IF(COUNTIF(Table2[[#This Row],[Employee_ID]],Table2[[#This Row],[Employee_ID]])=0,"Invalid Employee","OK") -> OK | Z23: =IF(Table2[[#This Row],[Stock_After]]=Table2[[#This Row],[Stock_After]]+Table2[[#This Row],[Stock_After]]-Table2[[#This Row],[Stock_After]]-Table2[[#This Row],[Stock_After]]+Table2[[#This Row],[Stock_After]],"OK","Error") -> OK | AA23: =IF(ROUND(Table2[[#This Row],[Total_Value]],2)=ROUND(Table2[[#This Row],[Quantity]]*Table2[[#This Row],[Unit_Price]],2),"OK","Error") -> OK | AB23: =IF(Table2[[#This Row],[Transaction_Type]]="Purchase", IF(Table2[[#This Row],[Stock_After]]=Table2[[#This Row],[Stock_Before]]+Table2[[#This Row],[Quantity]], "OK", "Error"), IF(Table2[[#This Row],[Transaction_Type]]="Return", IF(Table2[[#This Row],[Stock_After]]=Table2[[#This Row],[Stock_Before]]+Table2[[#This Row],[Quantity]], "OK", "Error"), IF(Table2[[#This Row],[Transaction_Type]]="Sale", IF(Table2[[#This Row],[Stock_After]]=MAX(0, Table2[[#This Row],[Stock_Before]]-Table2[[#This Row],[Quantity]]), "OK", "Error"), IF(Table2[[#This Row],[Transaction_Type]]="Adjustment", IF(Table2[[#This Row],[Stock_After]]>=0, "OK", "Error"), "Check")))) -> OK | AC23: =IF(AND(Table2[[#This Row],[Quantity]]>=0,Table2[[#This Row],[Unit_Price]]>=0),"OK","Error") -> OK | AD23: =IF(Table2[[#This Row],[Stock_After]]=0,"Stock-Out",IF(Table2[[#This Row],[Stock_After]]<=10,"Low Stock","Healthy")) -> Healthy
A24: T00023 | B24: 46111 | C24: P007 | D24: Office Desk | E24: Furniture | F24: Desks | G24: S018 | H24: W01 | I24: Sale | J24: 36 | K24: 30368 | L24: 1093248 | M24: 177 | N24: 141 | O24: E002 | P24: C0448 | Q24: Cash | R24: Completed | S24: Regular Transaction | T24: =IF(COUNTIF(T26,Q36)>1,"Duplicate","OK") -> OK | U24: =IF(Table2[[#This Row],[Transaction_ID]]="","Missing","OK") -> OK | V24: =IF(COUNTIF(Table2[[#This Row],[Product_ID]],Table2[[#This Row],[Product_ID]])=0,"Invalid Product","OK") -> OK | W24: =IF(COUNTIF(Table2[[#This Row],[Supplier_ID]],Table2[[#This Row],[Supplier_ID]])=0,"Invalid Supplier","OK") -> OK | X24: =IF(COUNTIF(Table2[[#This Row],[Warehouse_ID]],Table2[[#This Row],[Warehouse_ID]])=0,"Invalid Warehouse","OK") -> OK | Y24: =IF(COUNTIF(Table2[[#This Row],[Employee_ID]],Table2[[#This Row],[Employee_ID]])=0,"Invalid Employee","OK") -> OK | Z24: =IF(Table2[[#This Row],[Stock_After]]=Table2[[#This Row],[Stock_After]]+Table2[[#This Row],[Stock_After]]-Table2[[#This Row],[Stock_After]]-Table2[[#This Row],[Stock_After]]+Table2[[#This Row],[Stock_After]],"OK","Error") -> OK | AA24: =IF(ROUND(Table2[[#This Row],[Total_Value]],2)=ROUND(Table2[[#This Row],[Quantity]]*Table2[[#This Row],[Unit_Price]],2),"OK","Error") -> OK | AB24: =IF(Table2[[#This Row],[Transaction_Type]]="Purchase", IF(Table2[[#This Row],[Stock_After]]=Table2[[#This Row],[Stock_Before]]+Table2[[#This Row],[Quantity]], "OK", "Error"), IF(Table2[[#This Row],[Transaction_Type]]="Return", IF(Table2[[#This Row],[Stock_After]]=Table2[[#This Row],[Stock_Before]]+Table2[[#This Row],[Quantity]], "OK", "Error"), IF(Table2[[#This Row],[Transaction_Type]]="Sale", IF(Table2[[#This Row],[Stock_After]]=MAX(0, Table2[[#This Row],[Stock_Before]]-Table2[[#This Row],[Quantity]]), "OK", "Error"), IF(Table2[[#This Row],[Transaction_Type]]="Adjustment", IF(Table2[[#This Row],[Stock_After]]>=0, "OK", "Error"), "Check")))) -> OK | AC24: =IF(AND(Table2[[#This Row],[Quantity]]>=0,Table2[[#This Row],[Unit_Price]]>=0),"OK","Error") -> OK | AD24: =IF(Table2[[#This Row],[Stock_After]]=0,"Stock-Out",IF(Table2[[#This Row],[Stock_After]]<=10,"Low Stock","Healthy")) -> Healthy
